<robot name="dumpUrdf">
	<link name="base" >
		<inertial>
				<origin rpy = "0 0 0" xyz = "0 0 0" />
			 <mass value = "0.0001" />
			<inertia ixx = "0.0001" ixy = "0" ixz = "0" iyy = "0.0001" iyz = "0" izz = "0.0001" />
		</inertial>
	</link>

<!-- root/torso -->
	<link name="root" >
		<inertial>
				<origin rpy = "0 0 0" xyz = "0.000000 0.280000 0.000000" />
			 <mass value = "18.000000" />
			<inertia ixx = "0.3" ixy = "0" ixz = "0" iyy = "0.3" iyz = "0" izz = "0.3" />
		</inertial>
		<collision>
				<origin rpy = "0 0 0" xyz = "0.000000 0.280000 0.000000" />
			<geometry>
				<sphere radius = "0.360000" />
			</geometry>
		</collision>
	</link>
	<joint name="root" type="fixed" >
		<parent link = "base" />
		<child link="root" />
				<origin rpy = "0 0 0" xyz = "0.000000 0.000000 0.000000" />
	</joint>

<!-- chest -->
    <link name="chest_f1">
        <inertial>
            <mass value="0."/>
            <origin xyz="0. 0. 0." rpy="0. 0. 0."/>
            <inertia ixx="0."  ixy="0." ixz="0." iyy="0." iyz="0." izz="0."/>
        </inertial>
    </link>
    <link name="chest_f2">
        <inertial>
            <mass value="0."/>
            <origin xyz="0. 0. 0." rpy="0. 0. 0."/>
            <inertia ixx="0."  ixy="0." ixz="0." iyy="0." iyz="0." izz="0."/>
        </inertial>
    </link>
	<link name="chest" >
		<inertial>
				<origin rpy = "0 0 0" xyz = "0.000000 0.480000 0.000000" />
			 <mass value = "18.000000" />
			<inertia ixx = "0.3" ixy = "0" ixz = "0" iyy = "0.3" iyz = "0" izz = "0.3" />
		</inertial>
		<collision>
				<origin rpy = "0 0 0" xyz = "0.000000 0.480000 0.000000" />
			<geometry>
				<sphere radius = "0.440000" />
			</geometry>
		</collision>
	</link>
    <joint name="chest_rotx" type="revolute">
        <parent link="root" />
		<child link="chest_f1" />
		<dynamics damping="5.0" friction="1.0"/>
		<limit effort="100.0" lower="-0.785" upper="0.785" velocity="0.5"/>
			<origin rpy = "0 0 0" xyz = "0.000000 0.944604 0.000000" />
		<axis xyz = "1.000000 0.000000 0.000000" />
    </joint>
    <joint name="chest_roty" type="revolute">
        <parent link="chest_f1" />
		<child link="chest_f2" />
		<dynamics damping="5.0" friction="1.0"/>
		<limit effort="100.0" lower="-0.523" upper="0.523" velocity="0.5"/>
			<origin rpy = "0 0 0" xyz = "0.000000 0.000000 0.000000" />
		<axis xyz = "0.000000 1.000000 0.000000" />
    </joint>
    <joint name="chest_rotz" type="revolute" >
		<parent link="chest_f2" />
		<child link="chest" />
		<dynamics damping="5.0" friction="1.0"/>
		<limit effort="100.0" lower="-0.785" upper="0.785" velocity="0.5"/>
			<origin rpy = "0 0 0" xyz = "0.000000 0.000000 0.000000" />
		<axis xyz = "0.000000 0.000000 1.000000" />
	</joint>  

<!-- neck/head -->
	<link name="neck_f1">
        <inertial>
            <mass value="0."/>
            <origin xyz="0. 0. 0." rpy="0. 0. 0."/>
            <inertia ixx="0."  ixy="0." ixz="0." iyy="0." iyz="0." izz="0."/>
        </inertial>
    </link>
	<link name="neck" >
		<inertial>
				<origin rpy = "0 0 0" xyz = "0.000000 0.700000 0.000000" />
			 <mass value = "2.000000" />
			<inertia ixx = "0.1" ixy = "0" ixz = "0" iyy = "0.1" iyz = "0" izz = "0.1" />
		</inertial>
		<collision>
				<origin rpy = "0 0 0" xyz = "0.000000 0.700000 0.000000" />
			<geometry>
				<sphere radius = "0.410000" />
			</geometry>
		</collision>
	</link>
	<joint name="neck_rotx" type="revolute">
        <parent link="chest" />
		<child link="neck_f1" />
		<dynamics damping="3.0" friction="1.0"/>
		<limit effort="100.0" lower="-0.785" upper="0.785" velocity="0.5"/>
			<origin rpy = "0 0 0" xyz = "0.000000 0.895576 0.000000" />
		<axis xyz = "1.000000 0.000000 0.000000" />
    </joint>
    <joint name="neck_rotz" type="revolute">
        <parent link="neck_f1" />
		<child link="neck" />
		<dynamics damping="3.0" friction="1.0"/>
		<limit effort="100.0" lower="-0.523" upper="0.523" velocity="0.5"/>
			<origin rpy = "0 0 0" xyz = "0.000000 0.000000 0.000000" />
		<axis xyz = "0.000000 0.000000 1.000000" />
    </joint>

<!-- right hip -->
    <link name="right_hip_f1">
        <inertial>
            <mass value="0."/>
            <origin xyz="0. 0. 0." rpy="0. 0. 0."/>
            <inertia ixx="0."  ixy="0." ixz="0." iyy="0." iyz="0." izz="0."/>
        </inertial>
    </link>
	<link name="right_hip" >
		<inertial>
				<origin rpy = "0 0 0" xyz = "0.000000 -0.840000 0.000000" />
			 <mass value = "7.00000" />
			<inertia ixx = "0.16" ixy = "0" ixz = "0" iyy = "0.16" iyz = "0" izz = "0.16" />
		</inertial>
		<collision>
				<origin rpy = "-1.570796 0 0" xyz = "0.000000 -0.840000 0.000000" />
			<geometry>
				<capsule length="1.200000" radius="0.220000"/>
			</geometry>
		</collision>
	</link>
    <joint name="right_hip_rotx" type="revolute">
        <parent link="root" />
		<child link="right_hip_f1" />
		<dynamics damping="5.0" friction="0.5"/>
		<limit effort="1000.0" lower="-0.523" upper="0.785" velocity="0.5"/>
			<origin rpy = "0 0 0" xyz = "0.000000 0.000000 0.339548" />
		<axis xyz = "1.000000 0.000000 0.000000" />
    </joint>
    <joint name="right_hip_rotz" type="revolute" >
		<parent link="right_hip_f1" />
		<child link="right_hip" />
		<dynamics damping="8.0" friction="0.5"/>
		<limit effort="8000.0" lower="-1.00" upper="2.09" velocity="0.5"/>
			<origin rpy = "0 0 0" xyz = "0.000000 0.000000 0.000000" />
		<axis xyz = "0.000000 0.000000 1.000000" />
	</joint>    
    
<!-- right knee -->
	<link name="right_knee" >
		<inertial>
				<origin rpy = "0 0 0" xyz = "0.000000 -0.800000 0.000000" />
			 <mass value = "3.000000" />
			<inertia ixx = "0.1" ixy = "0" ixz = "0" iyy = "0.1" iyz = "0" izz = "0.1" />
		</inertial>
		<collision>
				<origin rpy = "-1.570796 0 0" xyz = "0.000000 -0.800000 0.000000" />
			<geometry>
				<capsule length="1.240000" radius="0.200000"/>
			</geometry>
		</collision>
	</link>
	<joint name="right_knee" type="revolute" >
		<parent link="right_hip" />
		<child link="right_knee" />
		<dynamics damping="3.0" friction="1.0"/>
		<limit effort="100.0" lower="-2.09" upper="0." velocity="0.5"/>
			<origin rpy = "0 0 0" xyz = "0.000000 -1.686184 0.000000" />
		<axis xyz = "0.000000 0.000000 1.000000" />
	</joint>

<!-- left hip -->
    <link name="left_hip_f1">
        <inertial>
            <mass value="0."/>
            <origin xyz="0. 0. 0." rpy="0. 0. 0."/>
            <inertia ixx="0."  ixy="0." ixz="0." iyy="0." iyz="0." izz="0."/>
        </inertial>
    </link>
	<link name="left_hip" >
		<inertial>
				<origin rpy = "0 0 0" xyz = "0.000000 -0.840000 0.000000" />
			 <mass value = "7.00000" />
			<inertia ixx = "0.16" ixy = "0" ixz = "0" iyy = "0.16" iyz = "0" izz = "0.16" />
		</inertial>
		<collision>
				<origin rpy = "-1.570796 0 0" xyz = "0.000000 -0.840000 0.000000" />
			<geometry>
				<capsule length="1.200000" radius="0.220000"/>
			</geometry>
		</collision>
	</link>
    <joint name="left_hip_rotx" type="revolute">
        <parent link="root" />
		<child link="left_hip_f1" />
		<dynamics damping="5.0" friction="0.5"/>
		<limit effort="1000.0" lower="-0.785" upper="0.523" velocity="0.5"/>
			<origin rpy = "0 0 0" xyz = "0.000000 0.000000 -0.339548" />
		<axis xyz = "1.000000 0.000000 0.000000" />
    </joint>
    <joint name="left_hip_rotz" type="revolute" >
		<parent link="left_hip_f1" />
		<child link="left_hip" />
		<dynamics damping="8.0" friction="0.5"/>
		<limit effort="8000.0" lower="-1.00" upper="2.09" velocity="0.5"/>
			<origin rpy = "0 0 0" xyz = "0.000000 0.000000 0.000000" />
		<axis xyz = "0.000000 0.000000 1.000000" />
	</joint>

<!-- left knee -->
	<link name="left_knee" >
		<inertial>
				<origin rpy = "0 0 0" xyz = "0.000000 -0.800000 0.000000" />
			 <mass value = "3.000000" />
			<inertia ixx = "0.1" ixy = "0" ixz = "0" iyy = "0.1" iyz = "0" izz = "0.1" />
		</inertial>
		<collision>
				<origin rpy = "-1.570796 0 0" xyz = "0.000000 -0.800000 0.000000" />
			<geometry>
				<capsule length="1.240000" radius="0.200000"/>
			</geometry>
		</collision>
	</link>
	<joint name="left_knee" type="revolute" >
		<parent link="left_hip" />
		<child link="left_knee" />
		<dynamics damping="3.0" friction="1.0"/>
		<limit effort="100.0" lower="-2.09" upper="0." velocity="0.5"/>
				<origin rpy = "0 0 0" xyz = "0.000000 -1.686184 0.000000" />
		<axis xyz = "0.000000 0.000000 1.000000" />
	</joint>

<!-- left shoulder -->
    <link name="left_shoulder_f1">
        <inertial>
            <mass value="0."/>
            <origin xyz="0. 0. 0." rpy="0. 0. 0."/>
            <inertia ixx="0."  ixy="0." ixz="0." iyy="0." iyz="0." izz="0."/>
        </inertial>
    </link>
	<link name="left_shoulder_f2">
        <inertial>
            <mass value="0."/>
            <origin xyz="0. 0. 0." rpy="0. 0. 0."/>
            <inertia ixx="0."  ixy="0." ixz="0." iyy="0." iyz="0." izz="0."/>
        </inertial>
    </link>
	<link name="left_shoulder" >
		<inertial>
				<origin rpy = "0 0 0" xyz = "0.000000 -0.560000 0.000000" />
			 <mass value = "3.00000" />
			<inertia ixx = "0.2" ixy = "0" ixz = "0" iyy = "0.2" iyz = "0" izz = "0.2" />
		</inertial>
		<collision>
				<origin rpy = "-1.570796 0 0" xyz = "0.000000 -0.560000 0.000000" />
			<geometry>
				<capsule length="0.720000" radius="0.180000"/>
			</geometry>
		</collision>
	</link>
	<joint name="left_shoulder_rotz" type="revolute" >
		<parent link="chest" />
		<child link="left_shoulder_f1" />
		<origin rpy = "0 0 0" xyz = "-0.096200 0.974000 -0.732440" />
		<dynamics damping="2.0" friction="0.5"/>
		<limit effort="100.0" lower="-0.785" upper="3.14" velocity="0.5"/>
		<axis xyz = "0.000000 0.000000 1.000000" />
	</joint>
	<joint name="left_shoulder_roty" type="revolute" >
		<parent link="left_shoulder_f1" />
		<child link="left_shoulder_f2" />
		<origin rpy = "0 0 0" xyz = "0.0 0.0 0.0" />
		<dynamics damping="2.0" friction="0.5"/>
		<limit effort="100.0" lower="-0.785" upper="0.785" velocity="0.5"/>
		<axis xyz = "0.000000 1.000000 0.000000" />
	</joint>
	<joint name="left_shoulder_rotx" type="revolute" >
		<parent link="left_shoulder_f2" />
		<child link="left_shoulder" />
		<origin rpy = "0 0 0" xyz = "0.0 0.0 0.0" />
		<dynamics damping="2.0" friction="0.5"/>
		<limit effort="100.0" lower="-1.57" upper="0.0" velocity="0.5"/>
		<axis xyz = "1.000000 0.000000 0.000000" />
	</joint>

<!-- right shoulder -->
    <link name="right_shoulder_f1">
        <inertial>
            <mass value="0."/>
            <origin xyz="0. 0. 0." rpy="0. 0. 0."/>
            <inertia ixx="0."  ixy="0." ixz="0." iyy="0." iyz="0." izz="0."/>
        </inertial>
    </link>
	<link name="right_shoulder_f2">
        <inertial>
            <mass value="0."/>
            <origin xyz="0. 0. 0." rpy="0. 0. 0."/>
            <inertia ixx="0."  ixy="0." ixz="0." iyy="0." iyz="0." izz="0."/>
        </inertial>
    </link>
	<link name="right_shoulder" >
		<inertial>
				<origin rpy = "0 0 0" xyz = "0.000000 -0.560000 0.000000" />
			 <mass value = "3.00000" />
			<inertia ixx = "0.2" ixy = "0" ixz = "0" iyy = "0.2" iyz = "0" izz = "0.2" />
		</inertial>
		<collision>
				<origin rpy = "-1.570796 0 0" xyz = "0.000000 -0.560000 0.000000" />
			<geometry>
				<capsule length="0.720000" radius="0.180000"/>
			</geometry>
		</collision>
	</link>
	<joint name="right_shoulder_rotz" type="revolute" >
		<parent link="chest" />
		<child link="right_shoulder_f1" />
		<origin rpy = "0 0 0" xyz = "-0.096200 0.974000 0.732440" />
		<dynamics damping="2.0" friction="0.5"/>
		<limit effort="100.0" lower="-0.785" upper="3.14" velocity="0.5"/>
		<axis xyz = "0.000000 0.000000 1.000000" />
	</joint>
	<joint name="right_shoulder_roty" type="revolute" >
		<parent link="right_shoulder_f1" />
		<child link="right_shoulder_f2" />
		<origin rpy = "0 0 0" xyz = "0.0 0.0 0.0" />
		<dynamics damping="2.0" friction="0.5"/>
		<limit effort="100.0" lower="-0.785" upper="0.785" velocity="0.5"/>
		<axis xyz = "0.000000 1.000000 0.000000" />
	</joint>
	<joint name="right_shoulder_rotx" type="revolute" >
		<parent link="right_shoulder_f2" />
		<child link="right_shoulder" />
		<origin rpy = "0 0 0" xyz = "0.0 0.0 0.0" />
		<dynamics damping="2.0" friction="0.5"/>
		<limit effort="100.0" lower="0.0" upper="1.57" velocity="0.5"/>
		<axis xyz = "1.000000 0.000000 0.000000" />
	</joint>

</robot>